Workbook

Sheet PPM Monitoring-EV
A2: Step 1 : Selection of Quality and Process Performance Objective - QPPO (this comes from Business Objectives)
A3: Selected QPPO | B3: Effort Variance (b)
A6: Step 2 : Goal Setting for selected QPPO and Subprocesses (Probability of Success)
A7: Goal Setting
A8: Goal selection criteria | B8: Rationale for selecting Specification
A9: Organisational Level baselines | B9: Based on PPB 3 and PPB 4 data and Simulation outcomes.
A11: Current Probability of Success | B11: 0.988 | D11: Effort Variation | G11: Goal Setting for Sub Process
D12: LSL | E12: -0.28759058 | H12: LSL | J12: USL
D13: USL | E13: 0.32976042 | G13: Code review efficiency | H13: 0.040056007 | J13: 0.13948058
G14: Design Integration with application % | H14: 0.050371805 | J14: 0.1599413
G15: Requriement Analysis & SRS documentation % | H15: 0.34729721 | J15: 0.60313382
A17: Step 3 : Selection of PPM Equation
A18: Reference PPM | B18: PPB v 4.0 | L18: Criteria to identify Critical X
A19: Equation | B19: Effort Variance (b) = 1.133 - 3.876 * Design integration with application effort % - 0.967* Requirement analysis and SRS documentation effort % - 2.676 * Code review efficiency | L19: 1. "X" should be early in life cycle.
A20: Rationale for selecting PPM | B20: Effort variation is the factor which needs to be controlled in order to maintain Net Margin of the project. | L20: 2. "X" should have higher coefficient
A21: Selected Critical X | B21: Design integration with application effort %, Requirement analysis and SRS documentation effort %, Code review efficiency | L21: 3. "X" should be controllable.
A22: Rationale for selecting X | B22: Through sensitivity analysis
A24: Step 4 : Process Composition and Selection of Innovation for X factors
A25: Process Composition
A26: Process | B26: Sub-Process | D26: Sub-process X Factors | F26: Method Names
A27: SDLC | B27: Design and Development | D27: Design Integration with application % | F27: 1. Detailed Prototype 2. High Level Wireframe
A29: SDLC | B29: Requirement Development and Analysis | D29: Requirement Development and Analysis % | F29: 1. Reverse Presentation 2. Wireframe Demonstration
A31: SDLC | B31: Code Review | D31: Code Review Efficiency | F31: NA
A33: Process Composition (What-If Analysis)
A34: What IF Analysis
A35: WHAT-IF Analysis | B35: Case 1 | D35: Case 2 | F35: Case 3 | H35: Case 4
A36: Design Integration with application % | B36: 0.11988458 | D36: 0.11988458 | F36: 0.10178687 | H36: 0.10178687
A37: Requirement Development and Analysis % | B37: 0.45971621 | D37: 0.50332081 | F37: 0.45971621 | H37: 0.50332081
A38: Code Review Efficiency | B38: 0.089053438 | D38: 0.089053438 | F38: 0.089053438 | H38: 0.089053438
A39: Effort Variance (b) | B39: ='Raw data for EV'!$L$17+('Raw data for EV'!$L$18*'PPM Monitoring-EV'!B36)+('Raw data for EV'!$L$19*'PPM Monitoring-EV'!B37)+('Raw data for EV'!$L$20*'PPM Monitoring-EV'!B38) -> -0.014523164 | D39: ='Raw data for EV'!$L$17+('Raw data for EV'!$L$18*'PPM Monitoring-EV'!D36)+('Raw data for EV'!$L$19*'PPM Monitoring-EV'!D37)+('Raw data for EV'!$L$20*'PPM Monitoring-EV'!D38) -> -0.056721789 | F39: ='Raw data for EV'!$L$17+('Raw data for EV'!$L$18*'PPM Monitoring-EV'!F36)+('Raw data for EV'!$L$19*'PPM Monitoring-EV'!F37)+('Raw data for EV'!$L$20*'PPM Monitoring-EV'!F38) -> 0.055640275 | H39: ='Raw data for EV'!$L$17+('Raw data for EV'!$L$18*'PPM Monitoring-EV'!H36)+('Raw data for EV'!$L$19*'PPM Monitoring-EV'!H37)+('Raw data for EV'!$L$20*'PPM Monitoring-EV'!H38) -> 0.013441649
A40: Probability Of Success - Through Simulation
A41: Probability Of Success | B41: 0.999 | D41: 1 | F41: 1 | H41: 1
A42: Selected By Organisation | B42: Detailed Prototype & Reverse Presentation | D42: Detailed Prototype & Wireframe Demonstration | F42: Highlevel Wireframe & Reverse Presentation | H42: Highlevel Wireframe & Wireframe Demonstration
A43: Selected Innovation | B43: Yes | D43: Yes | F43: Yes | H43: Yes
A44: Priority | B44: Priority 2 | D44: Priority 1 | F44: Priority 1 | H44: Priority 1
A46: Step 5 : PPM Monitoring
A48: PPM Validation
A49: PPM Validation | B49: Project Name
C50: Sub-Project or Module Level | K50: Sub-Project or Module Level | S50: Sub-Project or Module Level
A51: Phase | B51: From Baselines | C51: From Planning (Refer combined Project Schedule) | D51: Monitoring Milestone 1 - (At the end of requirement phase) | E51: Monitoring Milestone 2 - (At the end of code review - Cycle 1) | F51: Monitoring Milestone 3 - (At the end of code review - Cycle 2) | G51: Monitoring Milestone 4 - (At the end of code review - Cycle 3) | H51: Monitoring Milestone 5 - (At the end of code review - Cycle 4) | I51: Monitoring Milestone 5 - (At the end of code review - Cycle 5) | J51: Monitoring Milestone 6 - (At the end of design and development phase) | K51: From Planning (Refer combined Project Schedule) | L51: Monitoring Milestone 1 - (At the end of requirement phase) | M51: Monitoring Milestone 2 - (At the end of code review - Cycle 1) | N51: Monitoring Milestone 3 - (At the end of code review - Cycle 2) | O51: Monitoring Milestone 4 - (At the end of code review - Cycle 3) | P51: Monitoring Milestone 5 - (At the end of code review - Cycle 4) | Q51: Monitoring Milestone 5 - (At the end of code review - Cycle 5) | R51: Monitoring Milestone 6 - (At the end of design and development phase) | S51: From Planning (Refer combined Project Schedule) | T51: Monitoring Milestone 1 - (At the end of requirement phase) | U51: Monitoring Milestone 2 - (At the end of code review - Cycle 1) | V51: Monitoring Milestone 3 - (At the end of code review - Cycle 2) | W51: Monitoring Milestone 4 - (At the end of code review - Cycle 3) | X51: Monitoring Milestone 5 - (At the end of code review - Cycle 4) | Y51: Monitoring Milestone 5 - (At the end of code review - Cycle 5) | Z51: Monitoring Milestone 6 - (At the end of design and development phase)
...

Sheet PPM Monitoring-Defect Rate
A2: Step 1 : Selection of Quality and Process Performance Objective - QPPO (this comes from Business Objectives)
A3: Selected QPPO | B3: Defect Rate
A6: Step 2 : Goal Setting for selected QPPO and Subprocesses (Probability of Success)
A7: Goal Setting
A8: Goal selection criteria | B8: Rationale for selecting Specification
A9: Organisational Level baselines | B9: Based on PPB 3 and PPB 4 data and Simulation outcomes.
A11: Current Probability of Success | B11: 0.62 | D11: Defect Rate | G11: Goal Setting for Sub Process
D12: LSL | E12: 0.012824268 | H12: LSL | J12: USL
D13: USL | E13: 0.048810628 | G13: % Review Effort | H13: 0.011001283 | J13: 0.087437162
G14: Design Review Efficiency | H14: 0.53571711 | J14: 1.3983179
A16: Step 3 : Selection of PPM Equation
A17: Reference PPM | B17: PPB | O17: Criteria to identify Critical X
A18: Equation | B18: Defect Rate = 0.1299 - ( 0.0564 x Design Review Efficiency) - (0.7151 x Review Effort%) Y = f(x) | O18: 1. "X" should be early in life cycle.
A19: Rationale for selecting PPM | B19: As defect rate is the factor which needs to be controlled in order to maintain better product quality. | O19: 2. "X" should have higher coefficient
A20: Selected Critical X | B20: Design Review Efficiency | O20: 3. "X" should be controllable.
A21: Rationale for selecting X | B21: Through Sensitivity Analysis. Because 'Design Review Efficiency" is a part of design and development milestone. This can be controlled.
A23: Step 4 : Process Composition and Selection of Innovation for X factors
A24: Process Composition
A25: Process | B25: Sub-Process | D25: Sub-process X Factors | F25: Method Names
A26: SDLC | B26: Design and Development | D26: Design Review Efficiency | F26: 1. Review by PM 2. Review by PM and SA
A28: SDLC | B28: Peer Review | D28: % Review Effort | F28: NA
A30: Process Composition (What-If Analysis)
A31: What IF Analysis
A32: WHAT-IF Analysis | B32: Case 1 | D32: Case 2 | F32: NA | H32: NA
A33: =D26 -> Design Review Efficiency | B33: 0.9095238 | D33: 1.0328572 | F33: NA | H33: NA
A34: =D28 -> % Review Effort | B34: 0.04301725 | D34: 0.04301725 | F34: NA | H34: NA
A35: Defect Rate | B35: ='Raw data for Defect rate'!$J$18+('Raw data for Defect rate'!$J$19*'PPM Monitoring-Defect Rate'!B33)+('Raw data for Defect rate'!$J$20*'PPM Monitoring-Defect Rate'!B34) -> 0.047858228 | D35: ='Raw data for Defect rate'!$J$18+('Raw data for Defect rate'!$J$19*'PPM Monitoring-Defect Rate'!D33)+('Raw data for Defect rate'!$J$20*'PPM Monitoring-Defect Rate'!D34) -> 0.040900972 | F35: NA | H35: NA
A36: Probability Of Success - Through Simulation
A37: Probability Of Success | B37: 0.567 | D37: 0.718 | F37: NA | H37: NA
A38: Selected By Organisation | B38: Design Review by PM | D38: Design Review by PM and SA | F38: NA | H38: NA
A39: Selected Innovation | B39: No | D39: Yes | F39: NA | H39: NA
A40: Priority | B40: Priority 2 | D40: Priority 1 | F40: NA | H40: NA
A43: Step 5 : PPM Monitoring
A45: PPM Validation
A46: PPM Validation | B46: Project Name
A47: Phase | B47: From Baselines | C47: For Planning (Refer Project Schedule) | D47: Monitoring Milestone 1 - (At end of requirement phase) | E47: Monitoring Milestone 1 - (At end of Design phase) | F47: Monitoring Milestone 1 - (At end of CUT phase) | G47: Monitoring Milestone 1 - (At end of Testing phase) | H47: Actual Values | I47: Closure Milestone
A48: Design Review Efficiency | B48: 0.89571429 | C48: =B48 -> 0.89571429 | D48: =C48 -> 0.89571429 | F48: =E48 -> 0 | G48: =F48 -> 0 | H48: =G48 -> 0 | I48: =H48 -> 0
A49: Review Effort % | B49: 0.038753754 | C49: 0.0426 | E49: 0.0328 | F49: 0.0328 | G49: 0.0328 | H49: 0.058217101 | I49: =H49 -> 0.058217101
A50: Low PI
A51: Predicted defect rate | B51: ='Raw data for Defect rate'!$J$18+('Raw data for Defect rate'!$J$19*B48)+('Raw data for Defect rate'!$J$20*B49) -> 0.051686186 | C51: ='Raw data for Defect rate'!$J$18+('Raw data for Defect rate'!$J$19*C48)+('Raw data for Defect rate'!$J$20*C49) -> 0.048935614 | D51: ='Raw data for Defect rate'!$J$18+('Raw data for Defect rate'!$J$19*D48)+('Raw data for Defect rate'!$J$20*D49) -> 0.079400221 | E51: ='Raw data for Defect rate'!$J$18+('Raw data for Defect rate'!$J$19*E48)+('Raw data for Defect rate'!$J$20*E49) -> 0.10647129 | F51: ='Raw data for Defect rate'!$J$18+('Raw data for Defect rate'!$J$19*F48)+('Raw data for Defect rate'!$J$20*F49) -> 0.10647129 | G51: ='Raw data for Defect rate'!$J$18+('Raw data for Defect rate'!$J$19*G48)+('Raw data for Defect rate'!$J$20*G49) -> 0.10647129 | H51: ='Raw data for Defect rate'!$J$18+('Raw data for Defect rate'!$J$19*H48)+('Raw data for Defect rate'!$J$20*H49) -> 0.088294716 | I51: ='Raw data for Defect rate'!$J$18+('Raw data for Defect rate'!$J$19*I48)+('Raw data for Defect rate'!$J$20*I49) -> 0.088294716
...

Sheet Subprocess Monitoring
A4: Sub Process (Critical X) Monitoring - Using Control Charts & Process Capability Analysis
A5: Control Chart (MR + IMR) for Critical X <to be copied from Minitab>
A7: Data Points | B7: Review Effort % | C7: Code Review Efficiency
A8: As per Monitoring milestones | C8: ='PPM Monitoring-EV'!E54 -> 0.66666667
C9: ='PPM Monitoring-EV'!F54 -> 0.5
C10: ='PPM Monitoring-EV'!G54 -> 0.8
C11: ='PPM Monitoring-EV'!H54 -> 1.5
C12: ='PPM Monitoring-EV'!I54 -> 0.16666667
C13: ='PPM Monitoring-EV'!J54 -> 0.6
C14: ='PPM Monitoring-EV'!M54 -> 0
C15: ='PPM Monitoring-EV'!N54 -> 0
C16: ='PPM Monitoring-EV'!O54 -> 0
C17: ='PPM Monitoring-EV'!P54 -> 0
C18: ='PPM Monitoring-EV'!Q54 -> 0
C19: ='PPM Monitoring-EV'!R54 -> 0
E36: Inference | I36: Inference | N36: Inference | T36: Inference | AA36: Inference
E37: All points are within control, so data is stable. | I37: All points are within control, so data is stable. | N37: All points are within control, so data is stable. | T37: All points are within control, so data is stable. | AA37: All points are within control, so data is stable.
A48: Step: Root Cause Analysis
A50: Sl. No. | C50: QPPO | D50: Metric Name | E50: Actual Observation | F50: Causal Analysis | K50: Actions ahead | M50: Target Date | N50: Closure Date | O50: Preventive Action | P50: Target Date | Q50: Closure Date
F51: Why 1 | G51: Why 2 | H51: Why 3 | I51: Why 4 | J51: Why 5 (Root Cause) | L51: Priority

Sheet Data for Subprocess Monitoring
A1: Order of completion | B1: Tasks | C1: Planned Effort | D1: Actual Effort | E1: Total Size | F1: Module Development Productivity
A2: 1 | B2: Module Development and MIS Report | C2: 320 | D2: 302 | E2: =C2/32 -> 10 | F2: =E2/D2 -> 0.033112583
A3: 2 | B3: Home Page and Dashboard Development | C3: 84 | D3: 80 | E3: =C3/8 -> 10.5 | F3: =E3/D3 -> 0.13125
D4: Total Size | E4: =SUM(E2:E3) -> 20.5
E6: Mean | F6: =AVERAGE(F2:F3) -> 0.082181291
E7: Standard Deviation | F7: =STDEV(F2:F3) -> 0.069393633
E8: USL | F8: =F6+(3*F7) -> 0.29036219
E9: LSL | F9: =F6-(3*F7) -> -0.12599961

Sheet Raw data for EV
E1: PPM FOR EV | K1: SUMMARY OUTPUT
E2: Effort Variance (revised) | F2: Design Integration with appli_1 | G2: Requriement Analysis & SRS doc_1 | H2: Code review efficiency
A3: Cycle - 4 | B3: Closed | C3: DERC-1016-100897 | D3: DERC (Website) | E3: -0.29419662 | F3: 0.15 | G3: 0.49042904 | H3: 0.13956734 | K3: Regression Statistics
A4: Cycle-5 | B4: UAT | C4: eGOV-FY2021-0025 | D4: ODISHA SWF | E4: -0.28653948 | F4: 0.14005102 | G4: 0.52993806 | H4: 0.13090909 | K4: Multiple R | L4: 0.975709
A5: Cycle-4 | B5: UAT | C5: eGOV-FY2021-0009 | D5: DOC | E5: -0.21783626 | F5: 0.12954876 | G5: 0.50980392 | H5: 0.11111111 | K5: R Square | L5: 0.95200805
A6: Cycle-5 | B6: Closed | C6: eGOV-FY2021-0001 | D6: NCPUL | E6: -0.10050319 | F6: 0.12 | G6: 0.49157303 | H6: 0.090909091 | K6: Adjusted R Square | L6: 0.92801207
A7: Cycle - 4 | B7: Closed | C7: Forest-1294-101168 | D7: Forest Department, Manipur (Website) | E7: -0.086528315 | F7: 0.16 | G7: 0.55 | H7: 0.04 | K7: Standard Error | L7: 0.066058117
A8: Cycle - 4 | B8: Closed | C8: HPL-651-100536 | D8: HPL | E8: -0.072247706 | F8: 0.099536061 | G8: 0.60352423 | H8: 0.089686099 | K8: Observations | L8: 10
A9: Cycle - 3 | B9: Closed | C9: GSnDS-826-100404 | D9: GSDS | E9: 0.17008197 | F9: 0.089795918 | G9: 0.448 | H9: 0.1
A10: Cycle - 3 | B10: Closed | C10: MWnCD-827-100405 | D10: MSK | E10: 0.28281429 | F10: 0.079989567 | G10: 0.34705882 | H10: 0.071428571 | K10: ANOVA
A11: Cycle - 3 | B11: Closed | C11: DOEOPWD-602-100180 | D11: AIC | E11: 0.29269731 | F11: 0.071143502 | G11: 0.4494382 | H11: 0.076923077 | L11: df | M11: SS | N11: MS | O11: F | P11: Significance F
A12: Cycle - 3 | B12: Closed | C12: APMS-632-100210 | D12: APMS | E12: 0.33481525 | F12: 0.050194721 | G12: 0.43902439 | H12: 0.04 | K12: Regression | L12: 3 | M12: 0.51936876 | N12: 0.17312292 | O12: 39.673653 | P12: 0.00023740408
K13: Residual | L13: 6 | M13: 0.026182049 | N13: 0.0043636748
K14: Total | L14: 9 | M14: 0.54555081
L16: Coefficients | M16: Standard Error | N16: t Stat | O16: P-value | P16: Lower 95% | Q16: Upper 95% | R16: Lower 95.0% | S16: Upper 95.0%
K17: Intercept | L17: 1.1334927 | M17: 0.16085103 | N17: 7.0468477 | O17: 0.00040842211 | P17: 0.73990444 | Q17: 1.527081 | R17: 0.73990444 | S17: 1.527081
K18: Design Integration with appli_1 | L18: -3.8769231 | M18: 0.80693939 | N18: -4.8044787 | O18: 0.0029870371 | P18: -5.8514327 | Q18: -1.9024136 | R18: -5.8514327 | S18: -1.9024136
K19: Requriement Analysis & SRS doc_1 | L19: -0.9677561 | M19: 0.38051212 | N19: -2.543299 | O19: 0.043885239 | P19: -1.8988357 | Q19: -0.036676485 | R19: -1.8988357 | S19: -0.036676485
K20: Code review efficiency | L20: -2.6763641 | M20: 0.73540894 | N20: -3.6392869 | O20: 0.010844118 | P20: -4.475845 | Q20: -0.87688329 | R20: -4.475845 | S20: -0.87688329
K22: 1.133 - 3.876 * Design integration with application - 0.967* Requirement analysis and SRS documentation - 2.676 * Code review efficiency

Sheet Raw data for Defect rate
E1: PPM FOR DEFECT RATE
E2: Defect Rate | F2: Design Review Efficiency= Design Review Defects / Design Review Effort spent | G2: % Review Effort = (Requirement Review Effort + Design Review Effort + Code Review Effort + Testing Review Effort) / Actual Effort | I2: SUMMARY OUTPUT
A3: Cycle - 3 | B3: Closed | C3: MWnCD-827-100405 | D3: MSK | E3: 0.020936 | F3: 1.4 | G3: 0.063586
A4: Cycle - 3 | B4: Closed | C4: DOEOPWD-602-100180 | D4: AIC | E4: 0.049411 | F4: 1 | G4: 0.009442 | I4: Regression Statistics
A5: Cycle - 3 | B5: Closed | C5: GSnDS-826-100404 | D5: GSDS | E5: 0.045534 | F5: 1 | G5: 0.022767 | I5: Multiple R | J5: 0.92837085
A6: Cycle - 4 | B6: Closed | C6: DERC-1016-100897 | D6: DERC (Website) | E6: 0.08836 | F6: 0.5 | G6: 0.015543 | I6: R Square | J6: 0.86187244
A7: Cycle - 4 | B7: Closed | C7: Forest-1294-101168 | D7: Forest Department, Manipur (Website) | E7: 0.09742 | F7: 0.714286 | G7: 0.021756 | I7: Adjusted R Square | J7: 0.82240742
A8: Cycle-4 | B8: Testing | C8: eGOV-FY2021-0025 | D8: ODISHA SWF | E8: 0.007532 | F8: 1.333333 | G8: 0.06416 | I8: Standard Error | J8: 0.014190445
A9: Cycle-4 | B9: Testing | C9: eGOV-FY2021-0004 | D9: ODISHA ONE | E9: 0.005255 | F9: 0.95 | G9: 0.087485 | I9: Observations | J9: 10
A10: Cycle-4 | B10: UAT | C10: eGOV-FY2021-0009 | D10: DOC | E10: 0.075701 | F10: 0.714286 | G10: 0.0253645
A11: Cycle-5 | B11: UAT | C11: eGOV-FY2021-0025 | D11: ODISHA SWF | E11: 0.012767 | F11: 1 | G11: 0.074311 | I11: ANOVA
A12: Cycle-5 | B12: Closed | C12: eGOV-FY2021-0001 | D12: NCPUL | E12: 0.04088 | F12: 1.1 | G12: 0.045758 | J12: df | K12: SS | L12: MS | M12: F | N12: Significance F
I13: Regression | J13: 2 | K13: 0.0087953422 | L13: 0.0043976711 | M13: 21.838897 | N13: 0.00097944756
I14: Residual | J14: 7 | K14: 0.0014095812 | L14: 0.00020136874
I15: Total | J15: 9 | K15: 0.010204923
J17: Coefficients | K17: Standard Error | L17: t Stat | M17: P-value | N17: Lower 95% | O17: Upper 95% | P17: Lower 95.0% | Q17: Upper 95.0%
I18: Intercept | J18: 0.12992761 | K18: 0.017347169 | L18: 7.4898449 | M18: 0.00013848254 | N18: 0.088908069 | O18: 0.17094714 | P18: 0.088908069 | Q18: 0.17094714
I19: Design Review Efficiency | J19: -0.056410159 | K19: 0.020546489 | L19: -2.745489 | M19: 0.028690048 | N19: -0.10499488 | O19: -0.0078254326 | P19: -0.10499488 | Q19: -0.0078254326
I20: % Peer Review Effort | J20: -0.71513162 | K20: 0.20539949 | L20: -3.4816621 | M20: 0.010243253 | N20: -1.2008242 | O20: -0.22943901 | P20: -1.2008242 | Q20: -0.22943901
I22: Defect Rate = 0.1299 - ( 0.0564 * Design Review Efficiency) - (0.7151 * % Peer Review Effort)
